<!DOCTYPE html>
<html lang="en">

<head>
    <meta charset="UTF-8">
    <meta http-equiv="X-UA-Compatible" content="IE=edge">
    <meta name="viewport" content="width=device-width, initial-scale=1.0">
    <link rel="stylesheet" href="../base.css">
    <title>Document</title>
</head>

<body>
    <script>
        function makePizza(toppings = []) {
            return new Promise((resolve, reject) => {
                if (toppings.includes('pineapple')) {
                    reject(new Error("Don't put pineapple on pizza"));
                }
                const bakeTime = 500 + toppings.length * 200;
                setTimeout(() => {
                    resolve(`here is your 🍕 with ${toppings.join(', ')}`);
                }, bakeTime);
            });
        }

        // ERROR HANDLING
        // An Await rejected, will stop the remaining code of the function, unless you catch it.
        // ONLY IF WE HAVE AN "await fn().catch()"instruction, the rest of the code of our function RUNS"; unless, you have to run the rest of your code inside the catch(){} scope(***)

        // 1 - try catch------------------------------------------------------------

        async function go1() {
            try {
                // we can catch errors like window.doestntExist();
                // if the await function has an error, it stops there running the block scope code.
                const result = await makePizza(['pineapple']);
                console.log(result); // it doesn't runs
                console.log("If is there an error it doesn't runs");
            } catch (err) {
                // (***)
                console.log(err);
                console.log('if it happens an error, this will run later the error login');
            }
        }
        go1();

        // 2 - sort of MIX AND MATCHING of both worlds. async/await + .then() + .catch()-----------
        function handleStatus(stat) {
            console.log(stat);
        }

        async function go2() {
            // Using await + .catch()., the remaining code under the instruction RUNS.
            const result = await makePizza(['pineapple']).catch(handleStatus); // (***)
            console.log(result); // undefined
            console.log('we have some errors but this runs too');
            return result; // for .then() use;
        }
        const go2Promise = go2(); // it is not the result!..for that, use the .then();

        //----
        async function go3() {
            // 1st mark async
            window.dowstnExist();
            console.log(
                "THIS will run only if it's inside a try/catch. We can't do window.dowstnExist().catch(). It's not a Promise"
            );
        }
        // we can handle other errors like: window.dowstnExist(),(THE REST of the FUNCTION WILL STOP RUNNING since the error occurs) (****)
        const go3Promise = go3().catch(handleStatus); // 2nd, call Promise.catch();

        //---
        async function go() {
            const result = await makePizza(['pineapple']);
            return result; // for .then() use;
        }

        // MAKE A SAFE FUNCTION WITH A HOF(HIGH ORDER FUNCTION)(THE REST of the FUNCTION WILL STOP RUNNING since the error occurs) (****)
        // for errors related to AWAIT MARKED FUNCTIONS
        // usefull for Node.js, so all the pages can use the same error handling.
        function makeSafe(fn, handleStatus) {
            return function () {
                fn().catch(handleStatus);
            };
        }
        const safeGo = makeSafe(go, handleStatus);
        safeGo(); // I have to run this, it's a function!.

        // WE CAN DO THIS TOO:
        /* go()
            .then((result) => {
                console.log(result);
            })
            .catch(handleStatus); */

        // OR SOMETHING LIKE THIS TOO:
        /* async function goGo() {
            const result = await go();
        }
        goGo().catch(handleStatus); */
    </script>
</body>

</html>